<?xml version="1.0" ?>
<robot name="src" xmlns:xacro="http://www.ros.org/wiki/xacro">

  <link name="base_link">
    <inertial>
      <origin xyz="0.16610439816848285 -0.000917172832020149 0.04851435261181043" rpy="0 0 0"/>
      <mass value="2.967563365014638"/>
      <inertia ixx="0.011642" iyy="0.035651" izz="0.038255" ixy="0.000148" iyz="-9.3e-05" ixz="0.000342"/>
    </inertial>
    <visual>
      <origin xyz="0 0 0" rpy="0 0 0"/>
      <geometry>
        <mesh filename="package://src_description/meshes/center_lidar.stl" scale="0.001 0.001 0.001"/>
      </geometry>
      <material name="silver"/>
    </visual>
    <collision>
      <origin xyz="0 0 0" rpy="0 0 0"/>
      <geometry>
        <mesh filename="package://src_description/meshes/center_lidar.stl" scale="0.001 0.001 0.001"/>
      </geometry>
    </collision>
  </link>

  <link name="l_rear_wheel">
    <inertial>
      <origin xyz="0.000416078291276656 -0.020157083474482 0.000827146053683048" rpy="0 0 0" />
      <mass value="0.115203103310497" />
      <inertia ixx="3.76619524598008E-05" ixy="-5.82867896238268E-09" ixz="9.78735956742376E-09" iyy="6.30867844857624E-05" iyz="-1.1823408757557E-08" izz="3.76776670177481E-05" />
    </inertial>
    <visual>
      <origin xyz="0 0 0" rpy="0 0 0" />
      <geometry>
        <mesh filename="package://src_description/meshes/l_rear_wheel.STL" />
      </geometry>
      <material name="">
        <color rgba="0.792156862745098 0.819607843137255 0.933333333333333 1" />
      </material>
    </visual>
    <collision>
      <origin xyz="0 0 0" rpy="0 0 0" />
      <geometry>
        <mesh filename="package://src_description/meshes/l_rear_wheel.STL" />
      </geometry>
    </collision>
  </link>

  <joint name="l_rear_wheel" type="continuous">
    <origin xyz="-0.0945002035940863 0.11 0.0350003475684688" rpy="0 0 0" />
    <parent link="base_link" />
    <child link="l_rear_wheel" />
    <axis xyz="0 1 0" />
  </joint>

</robot>
