<?xml version="1.0"?>
<robot name="ip010" xmlns:xacro="http://www.ros.org/wiki/xacro">

  <link name="base_link">
    <inertial>
      <origin xyz="-0.010365884133191 -0.000576778488747551 0.0698064146454796" rpy="0 0 0" />
      <mass value="1.12083938753469" />
      <inertia ixx="0.00625390309602125" ixy="3.03054612238855E-05" ixz="0.000573867658783163" iyy="0.0080987780933677" iyz="-9.26731016583709E-06" izz="0.0136845094087104" />
    </inertial>
    <visual>
      <origin xyz="0 0 0" rpy="0 0 0" />
      <geometry>
        <mesh filename="package://ip010_description/meshes/base_link.STL" />
      </geometry>
      <material name="">
        <color rgba="0.43921568627451 0.43921568627451 0.43921568627451 1" />
      </material>
    </visual>
    <collision>
      <origin xyz="0 0 0" rpy="0 0 0" />
      <geometry>
        <mesh filename="package://ip010_description/meshes/base_link.STL" />
      </geometry>
    </collision>
  </link>

  <link name="l_rear_wheel">
    <inertial>
      <origin xyz="0.000416078291276656 -0.020157083474482 0.000827146053683048" rpy="0 0 0" />
      <mass value="0.115203103310497" />
      <inertia ixx="3.76619524598008E-05" ixy="-5.82867896238268E-09" ixz="9.78735956742376E-09" iyy="6.30867844857624E-05" iyz="-1.1823408757557E-08" izz="3.76776670177481E-05" />
    </inertial>
    <visual>
      <origin xyz="0 0 0" rpy="0 0 0" />
      <geometry>
        <mesh filename="package://ip010_description/meshes/l_rear_wheel.STL" />
      </geometry>
      <material name="">
        <color rgba="0.792156862745098 0.819607843137255 0.933333333333333 1" />
      </material>
    </visual>
    <collision>
      <origin xyz="0 0 0" rpy="0 0 0" />
      <geometry>
        <mesh filename="package://ip010_description/meshes/l_rear_wheel.STL" />
      </geometry>
    </collision>
  </link>

  <joint name="l_rear_wheel" type="continuous">
    <origin xyz="-0.0945002035940863 0.11 0.0350003475684688" rpy="0 0 0" />
    <parent link="base_link" />
    <child link="l_rear_wheel" />
    <axis xyz="0 1 0" />
  </joint>

  <link name="r_rear_wheel">
    <inertial>
      <origin xyz="0.000414013270580993 0.0201570841374701 0.000828181653934248" rpy="0 0 0" />
      <mass value="0.115203104348033" />
      <inertia ixx="3.76626622310331E-05" ixy="5.98907546101305E-09" ixz="1.0317087954516E-08" iyy="6.30867844864224E-05" iyz="1.17429752615601E-08" izz="3.76769572572774E-05" />
    </inertial>
    <visual>
      <origin xyz="0 0 0" rpy="0 0 0" />
      <geometry>
        <mesh filename="package://ip010_description/meshes/r_rear_wheel.STL" />
      </geometry>
      <material name="">
        <color rgba="0.792156862745098 0.819607843137255 0.933333333333333 1" />
      </material>
    </visual>
    <collision>
      <origin xyz="0 0 0" rpy="0 0 0" />
      <geometry>
        <mesh filename="package://ip010_description/meshes/r_rear_wheel.STL" />
      </geometry>
    </collision>
  </link>

  <joint name="r_rear_wheel" type="continuous">
    <origin xyz="-0.0944995996831282 -0.11 0.0350000447264209" rpy="0 0 0" />
    <parent link="base_link" />
    <child link="r_rear_wheel" />
    <axis xyz="0 1 0" />
  </joint>

  <link name="front_ballcaster">
    <inertial>
      <origin xyz="2.32896466001442E-10 1.88369250417493E-10 0.00930627232022497" rpy="0 0 0" />
      <mass value="0.0209327830608877" />
      <inertia ixx="1.48299880678707E-06" ixy="-1.7043650171883E-13" ixz="-7.73616758546749E-15" iyy="1.31107957877558E-06" iyz="-6.17056111578677E-15" izz="1.88921846876978E-06" />
    </inertial>
    <visual>
      <origin xyz="0 0 0" rpy="0 0 0" />
      <geometry>
        <mesh filename="package://ip010_description/meshes/front_ballcaster.STL" />
      </geometry>
      <material name="">
        <color rgba="0.752941176470588 0.752941176470588 0.752941176470588 1" />
      </material>
    </visual>
    <collision>
      <origin xyz="0 0 0" rpy="0 0 0" />
      <geometry>
        <mesh filename="package://ip010_description/meshes/front_ballcaster.STL" />
      </geometry>
    </collision>
  </link>

  <joint name="front_ballcaster" type="fixed">
    <origin xyz="0.0879999994802632 0 0.000999753890741178" rpy="0 0 0" />
    <parent link="base_link" />
    <child link="front_ballcaster" />
  </joint>

  <link name="center_lidar">
    <inertial>
      <origin xyz="0.00755339223480704 -0.00027896548418537 -0.0300022240938231" rpy="0 0 0" />
      <mass value="0.118327011344308" />
      <inertia ixx="3.75663376269071E-05" ixy="-1.04736914369223E-07" ixz="-4.28429420760351E-07" iyy="4.21124856446319E-05" iyz="9.24636933962534E-09" izz="4.65081881789805E-05" />
    </inertial>
    <visual>
      <origin xyz="0 0 0" rpy="0 0 0" />
      <geometry>
        <mesh filename="package://ip010_description/meshes/center_lidar.STL" />
      </geometry>
      <material name="">
        <color rgba="0.752941176470588 0.752941176470588 0.752941176470588 1" />
      </material>
    </visual>
    <collision>
      <origin xyz="0 0 0" rpy="0 0 0" />
      <geometry>
        <mesh filename="package://ip010_description/meshes/center_lidar.STL" />
      </geometry>
    </collision>
  </link>

  <joint name="center_lidar" type="fixed">
    <origin xyz="-0.0321033068699902 -4.99877536184437E-05 0.119000000000201" rpy="0 0 0" />
    <parent link="base_link" />
    <child link="center_lidar" />
    <!-- <axis xyz="0 0 -1" /> -->
  </joint>

  <link name="front_camera">
    <inertial>
      <origin xyz="-0.00497560083527254 5.6920614055489E-19 -0.00156090309940154" rpy="0 0 0" />
      <mass value="0.000679586163770489" />
      <inertia ixx="5.37689116983891E-08" ixy="6.67253526693495E-26" ixz="-5.56265931483273E-10" iyy="2.8597907949626E-08" iyz="-3.19408275992568E-24" izz="2.75239156052624E-08" />
    </inertial>
    <visual>
      <origin xyz="0 0 0" rpy="0 0 0" />
      <geometry>
        <mesh filename="package://ip010_description/meshes/front_camera.STL" />
      </geometry>
      <material name="">
        <color rgba="0.792156862745098 0.819607843137255 0.933333333333333 1" />
      </material>
    </visual>
    <collision>
      <origin xyz="0 0 0" rpy="0 0 0" />
      <geometry>
        <mesh filename="package://ip010_description/meshes/front_camera.STL" />
      </geometry>
    </collision>
  </link>

  <joint name="front_camera" type="fixed">
    <origin xyz="0.141847512071907 -0.000215421199799998 0.0680000000002" rpy="0 0 0" />
    <parent link="base_link" />
    <child link="front_camera" />
  </joint>

  <link name='imu_link' />
  
  <joint name="imu_joint" type="fixed">
    <origin xyz="-0.0945002035940863 0.0 0.0350003475684688" rpy="0 0 0" />
    <parent link="base_link" />
    <child link="imu_link" />
    <axis xyz="0 1 0" />
  </joint>

</robot>