<?xml version="1.0" ?>
<!-- =================================================================================== -->
<!-- |    This document was autogenerated by xacro from /home/kimsooyoung/djhrd_ws/src/djhrd_ros2/fusionbot_description/urdf/fusionbot.urdf.xacro | -->
<!-- |    EDITING THIS FILE BY HAND IS NOT RECOMMENDED                                 | -->
<!-- =================================================================================== -->
<robot name="fusionbot">
  <material name="silver">
    <color rgba="0.700 0.700 0.700 1.000"/>
  </material>
  <material name="white">
    <color rgba="1 1 1 0.6"/>
  </material>
  <material name="black">
    <color rgba="0 0 0 0.7"/>
  </material>
  <material name="red">
    <color rgba="1 0 0 1"/>
  </material>
  <material name="blue">
    <color rgba="0 0 0.8 1"/>
  </material>
  <gazebo>
    <plugin filename="libgazebo_ros_control.so" name="control"/>
  </gazebo>
  <gazebo reference="camera_link">
    <sensor name="zed_camera_left_sensor" type="camera">
      <update_rate>30.0</update_rate>
      <visualize>false</visualize>
      <always_on>1</always_on>
      <camera name="front_camera">
        <!-- math.atan(320 / 687.8065795898438) * 2 -->
        <horizontal_fov>0.8709216071359963</horizontal_fov>
        <image>
          <width>1280</width>
          <height>720</height>
          <format>R8G8B8</format>
          <!-- <format>B8G8R8</format> -->
        </image>
        <clip>
          <near>0.02</near>
          <far>300</far>
        </clip>
        <noise>
          <type>gaussian</type>
          <mean>0.0</mean>
          <stddev>0.00007</stddev>
        </noise>
      </camera>
      <plugin filename="libgazebo_ros_camera.so" name="camera_controller">
        <ros>
          <!-- <namespace>custom_ns</namespace> -->
          <argument>image_raw:=image_raw</argument>
          <argument>camera_info:=camera_info</argument>
        </ros>
        <camera_name>/front_camera</camera_name>
        <frame_name>camera_link</frame_name>
        <hack_baseline>0.07</hack_baseline>
      </plugin>
    </sensor>
  </gazebo>
  <gazebo reference="imu_link">
    <gravity>true</gravity>
    <sensor name="imu_sensor" type="imu">
      <always_on>true</always_on>
      <update_rate>100</update_rate>
      <visualize>true</visualize>
      <!-- <imu>
      <orientation>
        <x>
          <noise type="gaussian">
            <mean>0.0</mean>
            <stddev>2e-1</stddev>
          </noise>
        </x>
        <y>
          <noise type="gaussian">
            <mean>0.0</mean>
            <stddev>2e-1</stddev>
          </noise>
        </y>
        <z>
          <noise type="gaussian">
            <mean>0.0</mean>
            <stddev>2e-1</stddev>
          </noise>
        </z>
      </orientation>
      <angular_velocity>
        <x>
          <noise type="gaussian">
            <mean>0.0</mean>
            <stddev>2e-4</stddev>
          </noise>
        </x>
        <y>
          <noise type="gaussian">
            <mean>0.0</mean>
            <stddev>2e-4</stddev>
          </noise>
        </y>
        <z>
          <noise type="gaussian">
            <mean>0.0</mean>
            <stddev>2e-4</stddev>
          </noise>
        </z>
      </angular_velocity>
      <linear_acceleration>
        <x>
          <noise type="gaussian">
            <mean>0.0</mean>
            <stddev>1.7e-2</stddev>
          </noise>
        </x>
        <y>
          <noise type="gaussian">
            <mean>0.0</mean>
            <stddev>1.7e-2</stddev>
          </noise>
        </y>
        <z>
          <noise type="gaussian">
            <mean>0.0</mean>
            <stddev>1.7e-2</stddev>
          </noise>
        </z>
      </linear_acceleration>
    </imu> -->
      <topic>imu</topic>
      <plugin filename="libgazebo_ros_imu_sensor.so" name="imu_plugin">
        <topicName>imu</topicName>
        <bodyName>imu_link</bodyName>
        <updateRateHZ>100.0</updateRateHZ>
        <xyzOffset>0 0 0</xyzOffset>
        <rpyOffset>0 0 0</rpyOffset>
        <frameName>imu_link</frameName>
        <initialOrientationAsReference>false</initialOrientationAsReference>
        <ros>
          <namespace>/imu</namespace>
          <remapping>~/out:=data</remapping>
        </ros>
      </plugin>
      <pose>0 0 0 0 0 0</pose>
    </sensor>
  </gazebo>
  <gazebo reference="lidar_1">
    <sensor name="lidar" type="ray">
      <pose>0 0 0 0 0 0</pose>
      <always_on>true</always_on>
      <visualize>false</visualize>
      <update_rate>10</update_rate>
      <ray>
        <scan>
          <horizontal>
            <samples>360</samples>
            <resolution>1.000000</resolution>
            <min_angle>-3.14159</min_angle>
            <max_angle>3.14159</max_angle>
          </horizontal>
        </scan>
        <range>
          <min>0.2</min>
          <max>10.0</max>
          <resolution>0.05</resolution>
        </range>
        <noise>
          <type>gaussian</type>
          <mean>0.0</mean>
          <stddev>0.01</stddev>
        </noise>
      </ray>
      <plugin filename="libgazebo_ros_ray_sensor.so" name="scan">
        <ros>
          <remapping>~/out:=scan</remapping>
        </ros>
        <output_type>sensor_msgs/LaserScan</output_type>
        <frame_name>lidar_1</frame_name>
      </plugin>
    </sensor>
  </gazebo>
  <gazebo>
    <plugin filename="libgazebo_ros_joint_state_publisher.so" name="fusionbot_joint_state">
      <ros>
        <remapping>~/out:=joint_states</remapping>
      </ros>
      <update_rate>30</update_rate>
      <joint_name>right_wheel_joint</joint_name>
      <joint_name>left_wheel_joint</joint_name>
    </plugin>
  </gazebo>
  <gazebo>
    <plugin filename="libgazebo_ros_diff_drive.so" name="differential_drive_controller">
      <update_rate>30</update_rate>
      <left_joint>left_wheel_joint</left_joint>
      <right_joint>right_wheel_joint</right_joint>
      <wheel_separation>0.2</wheel_separation>
      <wheel_diameter>0.1</wheel_diameter>
      <max_wheel_torque>50</max_wheel_torque>
      <max_wheel_acceleration>1.0</max_wheel_acceleration>
      <command_topic>cmd_vel</command_topic>
      <publish_odom>1</publish_odom>
      <publish_odom_tf>1</publish_odom_tf>
      <publish_wheel_tf>0</publish_wheel_tf>
      <odometry_topic>odom</odometry_topic>
      <odometry_frame>odom</odometry_frame>
      <robot_base_frame>base_footprint</robot_base_frame>
    </plugin>
  </gazebo>
  <gazebo reference="base_link">
    <material>Gazebo/Silver</material>
    <mu1>0.5</mu1>
    <mu2>0.5</mu2>
    <selfCollide>true</selfCollide>
    <gravity>true</gravity>
  </gazebo>
  <gazebo reference="lidar_1">
    <material>Gazebo/Blue</material>
    <mu1>0.2</mu1>
    <mu2>0.2</mu2>
    <selfCollide>true</selfCollide>
  </gazebo>
  <gazebo reference="right_wheel_1">
    <material>Gazebo/Black</material>
    <mu1>100000.0</mu1>
    <mu2>100000.0</mu2>
    <selfCollide>true</selfCollide>
  </gazebo>
  <gazebo reference="left_wheel_1">
    <material>Gazebo/Black</material>
    <mu1>100000.0</mu1>
    <mu2>100000.0</mu2>
    <selfCollide>true</selfCollide>
  </gazebo>
  <link name="base_footprint"/>
  <link name="base_link">
    <inertial>
      <origin rpy="0 0 0" xyz="0.0037594591254762827 0.0 0.052804115668456025"/>
      <mass value="2.3079643337726483"/>
      <inertia ixx="0.00789" ixy="0.0" ixz="-0.000325" iyy="0.008347" iyz="0.0" izz="0.01475"/>
    </inertial>
    <visual>
      <origin rpy="0 0 0" xyz="0 0 0"/>
      <geometry>
        <mesh filename="model://fusionbot/meshes/fusionbot/base_link.stl" scale="0.001 0.001 0.001"/>
      </geometry>
      <material name="silver"/>
    </visual>
    <collision>
      <origin rpy="0 0 0" xyz="0 0 0"/>
      <geometry>
        <mesh filename="model://fusionbot/meshes/fusionbot/base_link.stl" scale="0.001 0.001 0.001"/>
      </geometry>
    </collision>
  </link>
  <link name="right_wheel_1">
    <inertial>
      <origin rpy="0 0 0" xyz="-5.790023100122029e-18 -0.012499999999999997 0.0"/>
      <mass value="0.1826050729899067"/>
      <inertia ixx="0.000124" ixy="-0.0" ixz="0.0" iyy="0.000228" iyz="0.0" izz="0.000124"/>
    </inertial>
    <visual>
      <origin rpy="0 0 0" xyz="-0.0 0.1 -0.05"/>
      <geometry>
        <mesh filename="model://fusionbot/meshes/fusionbot/right_wheel_1.stl" scale="0.001 0.001 0.001"/>
      </geometry>
      <material name="silver"/>
    </visual>
    <collision>
      <origin rpy="0 0 0" xyz="-0.0 0.1 -0.05"/>
      <geometry>
        <mesh filename="model://fusionbot/meshes/fusionbot/right_wheel_1.stl" scale="0.001 0.001 0.001"/>
      </geometry>
    </collision>
  </link>
  <link name="left_wheel_1">
    <inertial>
      <origin rpy="0 0 0" xyz="-5.790023100122029e-18 0.012499999999999997 0.0"/>
      <mass value="0.1826050729899067"/>
      <inertia ixx="0.000124" ixy="0.0" ixz="0.0" iyy="0.000228" iyz="-0.0" izz="0.000124"/>
    </inertial>
    <visual>
      <origin rpy="0 0 0" xyz="-0.0 -0.1 -0.05"/>
      <geometry>
        <mesh filename="model://fusionbot/meshes/fusionbot/left_wheel_1.stl" scale="0.001 0.001 0.001"/>
      </geometry>
      <material name="silver"/>
    </visual>
    <collision>
      <origin rpy="0 0 0" xyz="-0.0 -0.1 -0.05"/>
      <geometry>
        <mesh filename="model://fusionbot/meshes/fusionbot/left_wheel_1.stl" scale="0.001 0.001 0.001"/>
      </geometry>
    </collision>
  </link>
  <link name="lidar_1">
    <inertial>
      <origin rpy="0 0 0" xyz="0.0 0.0 0.012499999999999997"/>
      <mass value="0.7552585088770711"/>
      <inertia ixx="0.000271" ixy="0.0" ixz="0.0" iyy="0.000271" iyz="-0.0" izz="0.000463"/>
    </inertial>
    <visual>
      <origin rpy="0 0 0" xyz="-0.05 -0.0 -0.11"/>
      <geometry>
        <mesh filename="model://fusionbot/meshes/fusionbot/lidar_1.stl" scale="0.001 0.001 0.001"/>
      </geometry>
      <material name="silver"/>
    </visual>
    <collision>
      <origin rpy="0 0 0" xyz="-0.05 -0.0 -0.11"/>
      <geometry>
        <mesh filename="model://fusionbot/meshes/fusionbot/lidar_1.stl" scale="0.001 0.001 0.001"/>
      </geometry>
    </collision>
  </link>
  <link name="imu_link">
    <inertial>
      <mass value="0.01"/>
      <inertia ixx="0.01" ixy="0" ixz="0" iyy="0.01" iyz="0" izz="0.01"/>
    </inertial>
  </link>
  <link name="camera_link">
    <inertial>
      <mass value="0.01"/>
      <inertia ixx="0.01" ixy="0" ixz="0" iyy="0.01" iyz="0" izz="0.01"/>
    </inertial>
  </link>
  <joint name="base_link_joint" type="fixed">
    <origin rpy="0 0 0" xyz="0 0 0"/>
    <parent link="base_footprint"/>
    <child link="base_link"/>
  </joint>
  <joint name="right_wheel_joint" type="continuous">
    <origin rpy="0 0 0" xyz="0.0 -0.1 0.05"/>
    <parent link="base_link"/>
    <child link="right_wheel_1"/>
    <axis xyz="0.0 1.0 0.0"/>
  </joint>
  <joint name="left_wheel_joint" type="continuous">
    <origin rpy="0 0 0" xyz="0.0 0.1 0.05"/>
    <parent link="base_link"/>
    <child link="left_wheel_1"/>
    <axis xyz="0.0 1.0 0.0"/>
  </joint>
  <joint name="imu_joint" type="fixed">
    <origin rpy="0 0 0" xyz="0.0 0.0 0.05"/>
    <parent link="base_link"/>
    <child link="imu_link"/>
    <axis xyz="0.0 0.0 0.0"/>
  </joint>
  <joint name="camera_joint" type="fixed">
    <origin rpy="0 0 0" xyz="0.1 0.0 0.05"/>
    <parent link="base_link"/>
    <child link="camera_link"/>
    <axis xyz="0.0 0.0 0.0"/>
  </joint>
  <joint name="lidar_joint" type="fixed">
    <origin rpy="0 0 0" xyz="0.05 0.0 0.11"/>
    <parent link="base_link"/>
    <child link="lidar_1"/>
  </joint>
</robot>
